<?xml version="1.0" ?>
<!-- =================================================================================== -->
<!-- |    This document was autogenerated by xacro from single_arm_robot.xacro         | -->
<!-- |    EDITING THIS FILE BY HAND IS NOT RECOMMENDED                                 | -->
<!-- =================================================================================== -->
<robot name="ur5e_robot">
  <!--
    Convenience wrapper for the 'ur_robot' macro which provides default values
    for the various "parameters files" parameters for a UR5e.

    This file can be used when composing a more complex scene with one or more
    UR5e robots.

    While the generic 'ur_robot' macro could also be used, it would require
    the user to provide values for all parameters, as that macro does not set
    any model-specific defaults (not even for the generic parameters, such as
    the visual and physical parameters and joint limits).

    Refer to the main 'ur_macro.xacro' in this package for information about
    use, contributors and limitations.

    NOTE: users will most likely want to override *at least* the
          'kinematics_parameters_file' parameter. Otherwise, a default kinematic
          model will be used, which will almost certainly not correspond to any
          real robot.
  -->
  <!--
    Base UR robot series xacro macro.

    NOTE: this is NOT a URDF. It cannot directly be loaded by consumers
    expecting a flattened '.urdf' file. See the top-level '.xacro' for that
    (but note: that .xacro must still be processed by the xacro command).

    For use in '.launch' files: use one of the 'load_urX.launch' convenience
    launch files.

    This file models the base kinematic chain of a UR robot, which then gets
    parameterised by various configuration files to convert it into a UR3(e),
    UR5(e), UR10(e) or UR16e.

    NOTE: the default kinematic parameters (ie: link lengths, frame locations,
    offets, etc) do not correspond to any particular robot. They are defaults
    only. There WILL be non-zero offsets between the Forward Kinematics results
    in TF (ie: robot_state_publisher) and the values reported by the Teach
    Pendant.

    For accurate (and robot-specific) transforms, the 'kinematics_parameters_file'
    parameter MUST point to a .yaml file containing the appropriate values for
    the targetted robot.

    If using the UniversalRobots/Universal_Robots_ROS_Driver, follow the steps
    described in the readme of that repository to extract the kinematic
    calibration from the controller and generate the required .yaml file.

    Main author of the migration to yaml configs: Ludovic Delval.

    Contributors to previous versions (in no particular order):

     - Felix Messmer
     - Kelsey Hawkins
     - Wim Meeussen
     - Shaun Edwards
     - Nadia Hammoudeh Garcia
     - Dave Hershberger
     - G. vd. Hoorn
     - Philip Long
     - Dave Coleman
     - Miguel Prada
     - Mathias Luedtke
     - Marcel Schnirring
     - Felix von Drigalski
     - Felix Exner
     - Jimmy Da Silva
     - Ajit Krisshna N L
     - Muhammad Asif Rana
  -->
  <!--
    NOTE: the macro defined in this file is NOT part of the public API of this
          package. Users CANNOT rely on this file being available, or stored in
          this location. Nor can they rely on the existence of the macro.
  -->
  <transmission name="shoulder_pan_trans">
    <type>transmission_interface/SimpleTransmission</type>
    <joint name="shoulder_pan_joint">
      <hardwareInterface>hardware_interface/PositionJointInterface</hardwareInterface>
    </joint>
    <actuator name="shoulder_pan_motor">
      <mechanicalReduction>1</mechanicalReduction>
    </actuator>
  </transmission>
  <transmission name="shoulder_lift_trans">
    <type>transmission_interface/SimpleTransmission</type>
    <joint name="shoulder_lift_joint">
      <hardwareInterface>hardware_interface/PositionJointInterface</hardwareInterface>
    </joint>
    <actuator name="shoulder_lift_motor">
      <mechanicalReduction>1</mechanicalReduction>
    </actuator>
  </transmission>
  <transmission name="elbow_trans">
    <type>transmission_interface/SimpleTransmission</type>
    <joint name="elbow_joint">
      <hardwareInterface>hardware_interface/PositionJointInterface</hardwareInterface>
    </joint>
    <actuator name="elbow_motor">
      <mechanicalReduction>1</mechanicalReduction>
    </actuator>
  </transmission>
  <transmission name="wrist_1_trans">
    <type>transmission_interface/SimpleTransmission</type>
    <joint name="wrist_1_joint">
      <hardwareInterface>hardware_interface/PositionJointInterface</hardwareInterface>
    </joint>
    <actuator name="wrist_1_motor">
      <mechanicalReduction>1</mechanicalReduction>
    </actuator>
  </transmission>
  <transmission name="wrist_2_trans">
    <type>transmission_interface/SimpleTransmission</type>
    <joint name="wrist_2_joint">
      <hardwareInterface>hardware_interface/PositionJointInterface</hardwareInterface>
    </joint>
    <actuator name="wrist_2_motor">
      <mechanicalReduction>1</mechanicalReduction>
    </actuator>
  </transmission>
  <transmission name="wrist_3_trans">
    <type>transmission_interface/SimpleTransmission</type>
    <joint name="wrist_3_joint">
      <hardwareInterface>hardware_interface/PositionJointInterface</hardwareInterface>
    </joint>
    <actuator name="wrist_3_motor">
      <mechanicalReduction>1</mechanicalReduction>
    </actuator>
  </transmission>
  <!-- links: main serial chain -->
  <link name="base_link"/>
  <link name="base_link_inertia">
    <visual>
      <origin rpy="0 0 3.141592653589793" xyz="0 0 0"/>
      <geometry>
        <mesh filename="package://arm_robot_description/meshes/ur5e/visual/base.dae"/>
      </geometry>
      <material name="LightGrey">
        <color rgba="0.7 0.7 0.7 1.0"/>
      </material>
    </visual>
    <collision>
      <origin rpy="0 0 3.141592653589793" xyz="0 0 0"/>
      <geometry>
        <mesh filename="package://arm_robot_description/meshes/ur5e/collision/base.stl"/>
      </geometry>
    </collision>
    <inertial>
      <mass value="4.0"/>
      <origin rpy="0 0 0" xyz="0 0 0"/>
      <inertia ixx="0.00443333156" ixy="0.0" ixz="0.0" iyy="0.00443333156" iyz="0.0" izz="0.0072"/>
    </inertial>
  </link>
  <link name="shoulder_link">
    <visual>
      <origin rpy="0 0 3.141592653589793" xyz="0 0 0"/>
      <geometry>
        <mesh filename="package://arm_robot_description/meshes/ur5e/visual/shoulder.dae"/>
      </geometry>
      <material name="LightGrey">
        <color rgba="0.7 0.7 0.7 1.0"/>
      </material>
    </visual>
    <collision>
      <origin rpy="0 0 3.141592653589793" xyz="0 0 0"/>
      <geometry>
        <mesh filename="package://arm_robot_description/meshes/ur5e/collision/shoulder.stl"/>
      </geometry>
    </collision>
    <inertial>
      <mass value="3.7"/>
      <origin rpy="0 0 0" xyz="0 0 0"/>
      <inertia ixx="0.010267495893" ixy="0.0" ixz="0.0" iyy="0.010267495893" iyz="0.0" izz="0.00666"/>
    </inertial>
  </link>
  <link name="upper_arm_link">
    <visual>
      <origin rpy="1.5707963267948966 0 -1.5707963267948966" xyz="0 0 0.138"/>
      <geometry>
        <mesh filename="package://arm_robot_description/meshes/ur5e/visual/upperarm.dae"/>
      </geometry>
      <material name="LightGrey">
        <color rgba="0.7 0.7 0.7 1.0"/>
      </material>
    </visual>
    <collision>
      <origin rpy="1.5707963267948966 0 -1.5707963267948966" xyz="0 0 0.138"/>
      <geometry>
        <mesh filename="package://arm_robot_description/meshes/ur5e/collision/upperarm.stl"/>
      </geometry>
    </collision>
    <inertial>
      <mass value="8.393"/>
      <origin rpy="0 1.5707963267948966 0" xyz="-0.2125 0.0 0.138"/>
      <inertia ixx="0.1338857818623325" ixy="0.0" ixz="0.0" iyy="0.1338857818623325" iyz="0.0" izz="0.0151074"/>
    </inertial>
  </link>
  <link name="forearm_link">
    <visual>
      <origin rpy="1.5707963267948966 0 -1.5707963267948966" xyz="0 0 0.007"/>
      <geometry>
        <mesh filename="package://arm_robot_description/meshes/ur5e/visual/forearm.dae"/>
      </geometry>
      <material name="LightGrey">
        <color rgba="0.7 0.7 0.7 1.0"/>
      </material>
    </visual>
    <collision>
      <origin rpy="1.5707963267948966 0 -1.5707963267948966" xyz="0 0 0.007"/>
      <geometry>
        <mesh filename="package://arm_robot_description/meshes/ur5e/collision/forearm.stl"/>
      </geometry>
    </collision>
    <inertial>
      <mass value="2.275"/>
      <origin rpy="0 1.5707963267948966 0" xyz="-0.1961 0.0 0.007"/>
      <inertia ixx="0.031209355099586295" ixy="0.0" ixz="0.0" iyy="0.031209355099586295" iyz="0.0" izz="0.004095"/>
    </inertial>
  </link>
  <link name="wrist_1_link">
    <visual>
      <!-- TODO: Move this to a parameter -->
      <origin rpy="1.5707963267948966 0 0" xyz="0 0 -0.127"/>
      <geometry>
        <mesh filename="package://arm_robot_description/meshes/ur5e/visual/wrist1.dae"/>
      </geometry>
      <material name="LightGrey">
        <color rgba="0.7 0.7 0.7 1.0"/>
      </material>
    </visual>
    <collision>
      <origin rpy="1.5707963267948966 0 0" xyz="0 0 -0.127"/>
      <geometry>
        <mesh filename="package://arm_robot_description/meshes/ur5e/collision/wrist1.stl"/>
      </geometry>
    </collision>
    <inertial>
      <mass value="1.219"/>
      <origin rpy="0 0 0" xyz="0 0 0"/>
      <inertia ixx="0.0025598989760400002" ixy="0.0" ixz="0.0" iyy="0.0025598989760400002" iyz="0.0" izz="0.0021942"/>
    </inertial>
  </link>
  <link name="wrist_2_link">
    <visual>
      <origin rpy="0 0 0" xyz="0 0 -0.0997"/>
      <geometry>
        <mesh filename="package://arm_robot_description/meshes/ur5e/visual/wrist2.dae"/>
      </geometry>
      <material name="LightGrey">
        <color rgba="0.7 0.7 0.7 1.0"/>
      </material>
    </visual>
    <collision>
      <origin rpy="0 0 0" xyz="0 0 -0.0997"/>
      <geometry>
        <mesh filename="package://arm_robot_description/meshes/ur5e/collision/wrist2.stl"/>
      </geometry>
    </collision>
    <inertial>
      <mass value="1.219"/>
      <origin rpy="0 0 0" xyz="0 0 0"/>
      <inertia ixx="0.0025598989760400002" ixy="0.0" ixz="0.0" iyy="0.0025598989760400002" iyz="0.0" izz="0.0021942"/>
    </inertial>
  </link>
  <link name="wrist_3_link">
    <visual>
      <origin rpy="1.5707963267948966 0 0" xyz="0 0 -0.0989"/>
      <geometry>
        <mesh filename="package://arm_robot_description/meshes/ur5e/visual/wrist3.dae"/>
      </geometry>
      <material name="LightGrey">
        <color rgba="0.7 0.7 0.7 1.0"/>
      </material>
    </visual>
    <collision>
      <origin rpy="1.5707963267948966 0 0" xyz="0 0 -0.0989"/>
      <geometry>
        <mesh filename="package://arm_robot_description/meshes/ur5e/collision/wrist3.stl"/>
      </geometry>
    </collision>
    <inertial>
      <mass value="0.1879"/>
      <origin rpy="0 0 0" xyz="0.0 0.0 -0.0229"/>
      <inertia ixx="9.890410052167731e-05" ixy="0.0" ixz="0.0" iyy="9.890410052167731e-05" iyz="0.0" izz="0.0001321171875"/>
    </inertial>
  </link>
  <!-- joints: main serial chain -->
  <joint name="base_link-base_link_inertia" type="fixed">
    <parent link="base_link"/>
    <child link="base_link_inertia"/>
    <!-- 'base_link' is REP-103 aligned (so X+ forward), while the internal
           frames of the robot/controller have X+ pointing backwards.
           Use the joint between 'base_link' and 'base_link_inertia' (a dummy
           link/frame) to introduce the necessary rotation over Z (of pi rad).
      -->
    <origin rpy="0 0 3.141592653589793" xyz="0 0 0"/>
  </joint>
  <joint name="shoulder_pan_joint" type="revolute">
    <parent link="base_link_inertia"/>
    <child link="shoulder_link"/>
    <origin rpy="0 0 5.921646436743422e-08" xyz="0 0 0.1627297657342701"/>
    <axis xyz="0 0 1"/>
    <limit effort="150.0" lower="-6.283185307179586" upper="6.283185307179586" velocity="3.141592653589793"/>
    <dynamics damping="0" friction="0"/>
  </joint>
  <joint name="shoulder_lift_joint" type="revolute">
    <parent link="shoulder_link"/>
    <child link="upper_arm_link"/>
    <origin rpy="1.571350908778415 0 -3.085572842734852e-06" xyz="0.0001588353640365326 0 0"/>
    <axis xyz="0 0 1"/>
    <limit effort="150.0" lower="-6.283185307179586" upper="6.283185307179586" velocity="3.141592653589793"/>
    <dynamics damping="0" friction="0"/>
  </joint>
  <joint name="elbow_joint" type="revolute">
    <parent link="upper_arm_link"/>
    <child link="forearm_link"/>
    <origin rpy="0.0003200011350069759 -0.0002227248904285447 -1.085352311177093e-06" xyz="-0.4251005603256471 0 0"/>
    <axis xyz="0 0 1"/>
    <limit effort="150.0" lower="-3.141592653589793" upper="3.141592653589793" velocity="3.141592653589793"/>
    <dynamics damping="0" friction="0"/>
  </joint>
  <joint name="wrist_1_joint" type="revolute">
    <parent link="forearm_link"/>
    <child link="wrist_1_link"/>
    <origin rpy="0.007922150818238065 0.0001913312126438064 -2.456957013920244e-06" xyz="-0.3922314444721665 -0.001059811827050482 0.1337754960543269"/>
    <axis xyz="0 0 1"/>
    <limit effort="28.0" lower="-6.283185307179586" upper="6.283185307179586" velocity="3.141592653589793"/>
    <dynamics damping="0" friction="0"/>
  </joint>
  <joint name="wrist_2_joint" type="revolute">
    <parent link="wrist_1_link"/>
    <child link="wrist_2_link"/>
    <origin rpy="1.569787769915148 0 4.196170326140058e-08" xyz="-8.543141610977271e-05 -0.09959947723388803 0.0001004517720430495"/>
    <axis xyz="0 0 1"/>
    <limit effort="28.0" lower="-6.283185307179586" upper="6.283185307179586" velocity="3.141592653589793"/>
    <dynamics damping="0" friction="0"/>
  </joint>
  <joint name="wrist_3_joint" type="revolute">
    <parent link="wrist_2_link"/>
    <child link="wrist_3_link"/>
    <origin rpy="1.570601435882507 3.141592653589793 3.141592438200498" xyz="7.159022188747432e-05 0.09955984828462842 -1.940330991524593e-05"/>
    <axis xyz="0 0 1"/>
    <limit effort="28.0" lower="-6.283185307179586" upper="6.283185307179586" velocity="3.141592653589793"/>
    <dynamics damping="0" friction="0"/>
  </joint>
  <!-- ROS-Industrial 'base' frame: base_link to UR 'Base' Coordinates transform -->
  <link name="base"/>
  <joint name="base_link-base_fixed_joint" type="fixed">
    <!-- Note the rotation over Z of pi radians: as base_link is REP-103
           aligned (ie: has X+ forward, Y+ left and Z+ up), this is needed
           to correctly align 'base' with the 'Base' coordinate system of
           the UR controller.
      -->
    <origin rpy="0 0 3.141592653589793" xyz="0 0 0"/>
    <parent link="base_link"/>
    <child link="base"/>
  </joint>
  <!-- ROS-Industrial 'flange' frame: attachment point for EEF models -->
  <link name="flange"/>
  <joint name="wrist_3-flange" type="fixed">
    <parent link="wrist_3_link"/>
    <child link="flange"/>
    <origin rpy="0 -1.5707963267948966 -1.5707963267948966" xyz="0 0 0"/>
  </joint>
  <!-- ROS-Industrial 'tool0' frame: all-zeros tool frame -->
  <link name="tool0"/>
  <joint name="flange-tool0" type="fixed">
    <!-- default toolframe: X+ left, Y+ up, Z+ front -->
    <origin rpy="1.5707963267948966 0 1.5707963267948966" xyz="0 0 0"/>
    <parent link="flange"/>
    <child link="tool0"/>
  </joint>
  <!-- 在第一个URDF文件中添加以下代码（建议放在<xacro:ur5e_robot prefix=""/>之后） -->
  <link name="world"/>
  <!-- 定义根节点world（如果未定义） -->
  <joint name="base_to_world" type="fixed">
    <parent link="world"/>
    <!-- 父节点：根节点world -->
    <child link="base_link"/>
    <!-- 子节点：UR5e的基座link（无prefix，对应你的设置） -->
    <origin rpy="0 0 0" xyz="0 0 0"/>
    <!-- 基座在world中的初始位置，可根据需求调整 -->
    <axis xyz="0 0 0"/>
  </joint>
  <!-- ============================================== -->
  <!-- 新增：1. 相机法兰盘（挂载于wrist_3_link，Z偏移0mm） -->
  <!-- ============================================== -->
  <link name="camera_flange_link">
    <!-- 视觉模型：引用STL文件 -->
    <visual>
      <origin rpy="0 0 0" xyz="0 0 0"/>
      <!-- 方向不对可调整RPY（单位：弧度） -->
      <geometry>
        <mesh filename="package://ur_gazebo/meshes/tool_camera/102camera.STL"/>
      </geometry>
      <material name="camera_material">
        <color rgba="0.8 0.8 0.8 1.0"/>
        <!-- 灰色视觉效果 -->
      </material>
    </visual>
    <!-- 碰撞模型：复用视觉STL（简化碰撞检测） -->
    <collision>
      <origin rpy="0 0 0" xyz="0 0 0"/>
      <geometry>
        <mesh filename="package://ur_gazebo/meshes/tool_camera/102camera.STL"/>
      </geometry>
    </collision>
    <!-- 惯性参数：避免Gazebo仿真报错（需按实际重量调整） -->
    <inertial>
      <mass value="0.5"/>
      <!-- 假设重量0.5kg -->
      <inertia ixx="0.001" ixy="0.0" ixz="0.0" iyy="0.001" iyz="0.0" izz="0.001"/>
      <!-- 简化惯性矩阵 -->
    </inertial>
  </link>
  <!-- ============================================== -->
  <!-- 新增：2. RGI夹爪（挂载于wrist_3_link，Z偏移25mm） -->
  <!-- ============================================== -->
  <link name="rgi_gripper_link">
    <!-- 视觉模型：引用STL文件 -->
    <visual>
      <origin rpy="0 0 0" xyz="0 0 0"/>
      <!-- 方向不对可调整RPY（如pi/2绕X轴转90度） -->
      <geometry>
        <mesh filename="package://ur_gazebo/meshes/dh_pgi/RGI-100-22-O-S_3D_v3.0.STL"/>
      </geometry>
      <material name="gripper_material">
        <color rgba="0.2 0.6 0.8 1.0"/>
        <!-- 蓝色视觉效果 -->
      </material>
    </visual>
    <!-- 碰撞模型：复用视觉STL -->
    <collision>
      <origin rpy="0 0 0" xyz="0 0 0"/>
      <geometry>
        <mesh filename="package://ur_gazebo/meshes/dh_pgi/RGI-100-22-O-S_3D_v3.0.STL"/>
      </geometry>
    </collision>
    <!-- 惯性参数：按实际夹爪重量调整 -->
    <inertial>
      <mass value="1.2"/>
      <!-- 假设重量1.2kg -->
      <inertia ixx="0.005" ixy="0.0" ixz="0.0" iyy="0.005" iyz="0.0" izz="0.005"/>
      <!-- 简化惯性矩阵 -->
    </inertial>
  </link>
  <!-- 在此处修改相机支架相对于机械臂工具面的初始转角origin rpy -->
  <!-- 相机与wrist_3_link的固定关节（Z偏移0mm） -->
  <joint name="wrist3_to_camera_flange" type="fixed">
    <parent link="wrist_3_link"/>
    <!-- 父连杆：UR5e末端wrist_3_link（无prefix） -->
    <child link="camera_flange_link"/>
    <!-- 子连杆：相机法兰盘 -->
    <origin rpy="0 0 2.356194490192345" xyz="0 0 0"/>
    <!-- XYZ偏移：Z=0mm；RPY默认对齐 -->
  </joint>
  <!-- 在此处修改RGI夹爪相对于相机支架的初始转角 rpy -->
  <!-- 夹爪与相机法兰盘的固定关节（Z偏移25mm=0.025m） -->
  <joint name="camera_flange_to_rgi_gripper" type="fixed">
    <parent link="camera_flange_link"/>
    <!-- 父连杆：UR5e末端wrist_3_link（无prefix） -->
    <child link="rgi_gripper_link"/>
    <!-- 子连杆：RGI夹爪 -->
    <origin rpy="0 0 0" xyz="0 0 0.025"/>
    <!-- XYZ偏移：Z=0.025m；RPY默认对齐 -->
  </joint>
  <link name="camera_color_optical_frame"/>
  <joint name="tool0_to_camera_color_optical_frame" type="fixed">
    <origin rpy="-1.046623 0.013615 1.578408" xyz="-0.07037919100000001 -0.034991298 0.024626465"/>
    <parent link="tool0"/>
    <child link="camera_color_optical_frame"/>
    <axis xyz="0 0 0"/>
  </joint>
  <link name="rgi_tip"/>
  <joint name="wrist_3_to_rgi_tip" type="fixed">
    <origin rpy="0 0 0" xyz="0 0 0.207"/>
    <parent link="wrist_3_link"/>
    <child link="rgi_tip"/>
    <axis xyz="0 0 0"/>
  </joint>
</robot>

